Workbook

Sheet Task1
A2: Task 1: Data Preprocessing and Cleaning
A3: ● Eliminate duplicate post entries
A4: ● Standardize date and platform formats
A5: ● Ensure numeric columns (likes, impressions, ad spend, downloads) are correctly formatted
A6: ● Split multi-hashtag columns into separate entries
A8: Post ID | B8: Platform | C8: Date | D8: Content Type | E8: Post Text | F8: Likes | G8: Shares | H8: Comments | I8: Impressions | J8: Reach | K8: Clicks | L8: Hashtags 1 | M8: Hashtags seprate | N8: Campaign_Name | O8: Engagement_Rate | P8: Net_Engagement | Q8: Total_Budget | R8: ROI | S8: Start_Date | T8: End_Date | U8: Column | V8: Average_Before | W8: Average_During | X8: Uplift
A9: SP007 | B9: Twitter | C9: 45645 | D9: Story | E9: Get into the groove with our new drop! | F9: 4674 | G9: 409 | H9: 327 | I9: 20756 | J9: 63599 | K9: 212 | L9: #SoundtrackOfLife | M9: #NowPlaying | N9: ChillVibes | O9: =((Posts!$F2+Posts!$G2+Posts!$H2)/Posts!$I2)*100 -> 13.20051 | P9: =SUM(Table2[[#This Row],[Likes]],Table2[[#This Row],[Shares]],Table2[[#This Row],[Comments]]) -> 1842 | Q9: =_xlfn.IFS( Table2[[#This Row],[Campaign_Name]]="SummerBeats", 175000, Table2[[#This Row],[Campaign_Name]]="Wrapped2024", 225000, Table2[[#This Row],[Campaign_Name]]="ChillVibes", 200000, Table2[[#This Row],[Campaign_Name]]="IndieWave", 160000 ) -> 200000 | R9: =Table2[[#This Row],[Net_Engagement]]/Table2[[#This Row],[Total_Budget]] -> 0.00921 | S9: =_xlfn.IFS( Table2[[#This Row],[Campaign_Name]]="SummerBeats", DATE(2024,6,15), Table2[[#This Row],[Campaign_Name]]="Wrapped2024", DATE(2024,12,1), Table2[[#This Row],[Campaign_Name]]="ChillVibes", DATE(2025,1,10), Table2[[#This Row],[Campaign_Name]]="IndieWave", DATE(2025,3,1) ) -> 45667 | T9: =_xlfn.IFS( Table2[[#This Row],[Campaign_Name]]="SummerBeats", DATE(2024,7,15), Table2[[#This Row],[Campaign_Name]]="Wrapped2024", DATE(2024,12,31), Table2[[#This Row],[Campaign_Name]]="ChillVibes", DATE(2025,2,10), Table2[[#This Row],[Campaign_Name]]="IndieWave", DATE(2025,3,31) ) -> 45698 | U9: =IF(AND(C9>=$S$9,C9<=$T$9),"During","Before") -> Before | V9: =AVERAGEIF($U$9:$U$308,"Before",O9) -> 9.150637 | W9: =IFERROR(AVERAGEIF($U$9:$U$308,"During",O9),0) -> 10.935919 | X9: =(Table1[[#This Row],[Average_During]]-Table1[[#This Row],[Average_Before]])/Table1[[#This Row],[Average_Before]]*100 -> 19.509924
A10: SP106 | B10: Twitter | C10: 45677 | D10: Story | E10: New music just dropped. Hit play! | F10: 4619 | G10: 272 | H10: 57 | I10: 21334 | J10: 46292 | K10: 91 | L10: #SoundtrackOfLife | M10: #NowPlaying | N10: ChillVibes | O10: =((Posts!$F3+Posts!$G3+Posts!$H3)/Posts!$I3)*100 -> 8.7095335 | P10: =SUM(Table2[[#This Row],[Likes]],Table2[[#This Row],[Shares]],Table2[[#This Row],[Comments]]) -> 4954 | Q10: =_xlfn.IFS( Table2[[#This Row],[Campaign_Name]]="SummerBeats", 175000, Table2[[#This Row],[Campaign_Name]]="Wrapped2024", 225000, Table2[[#This Row],[Campaign_Name]]="ChillVibes", 200000, Table2[[#This Row],[Campaign_Name]]="IndieWave", 160000 ) -> 200000 | R10: =Table2[[#This Row],[Net_Engagement]]/Table2[[#This Row],[Total_Budget]] -> 0.02477 | S10: =_xlfn.IFS( Table2[[#This Row],[Campaign_Name]]="SummerBeats", DATE(2024,6,15), Table2[[#This Row],[Campaign_Name]]="Wrapped2024", DATE(2024,12,1), Table2[[#This Row],[Campaign_Name]]="ChillVibes", DATE(2025,1,10), Table2[[#This Row],[Campaign_Name]]="IndieWave", DATE(2025,3,1) ) -> 45667 | T10: =_xlfn.IFS( Table2[[#This Row],[Campaign_Name]]="SummerBeats", DATE(2024,7,15), Table2[[#This Row],[Campaign_Name]]="Wrapped2024", DATE(2024,12,31), Table2[[#This Row],[Campaign_Name]]="ChillVibes", DATE(2025,2,10), Table2[[#This Row],[Campaign_Name]]="IndieWave", DATE(2025,3,31) ) -> 45698 | U10: =IF(AND(C10>=$S$9,C10<=$T$9),"During","Before") -> During | V10: =AVERAGEIF($U$9:$U$308,"Before",O10) -> 9.2225707 | W10: =IFERROR(AVERAGEIF($U$9:$U$308,"During",O10),0) -> 9.8461233 | X10: =(Table1[[#This Row],[Average_During]]-Table1[[#This Row],[Average_Before]])/Table1[[#This Row],[Average_Before]]*100 -> 6.761158
A11: SP186 | B11: Twitter | C11: 45459 | D11: Story | E11: Explore the latest podcasts now. | F11: 4618 | G11: 312 | H11: 254 | I11: 22571 | J11: 29453 | K11: 197 | L11: #MusicForEveryone | M11: #NowPlaying | N11: ChillVibes | O11: =((Posts!$F4+Posts!$G4+Posts!$H4)/Posts!$I4)*100 -> 7.0477353 | P11: =SUM(Table2[[#This Row],[Likes]],Table2[[#This Row],[Shares]],Table2[[#This Row],[Comments]]) -> 2803 | Q11: =_xlfn.IFS( Table2[[#This Row],[Campaign_Name]]="SummerBeats", 175000, Table2[[#This Row],[Campaign_Name]]="Wrapped2024", 225000, Table2[[#This Row],[Campaign_Name]]="ChillVibes", 200000, Table2[[#This Row],[Campaign_Name]]="IndieWave", 160000 ) -> 200000 | R11: =Table2[[#This Row],[Net_Engagement]]/Table2[[#This Row],[Total_Budget]] -> 0.014015 | S11: =_xlfn.IFS( Table2[[#This Row],[Campaign_Name]]="SummerBeats", DATE(2024,6,15), Table2[[#This Row],[Campaign_Name]]="Wrapped2024", DATE(2024,12,1), Table2[[#This Row],[Campaign_Name]]="ChillVibes", DATE(2025,1,10), Table2[[#This Row],[Campaign_Name]]="IndieWave", DATE(2025,3,1) ) -> 45667 | T11: =_xlfn.IFS( Table2[[#This Row],[Campaign_Name]]="SummerBeats", DATE(2024,7,15), Table2[[#This Row],[Campaign_Name]]="Wrapped2024", DATE(2024,12,31), Table2[[#This Row],[Campaign_Name]]="ChillVibes", DATE(2025,2,10), Table2[[#This Row],[Campaign_Name]]="IndieWave", DATE(2025,3,31) ) -> 45698 | U11: =IF(AND(C11>=$S$9,C11<=$T$9),"During","Before") -> Before | V11: =AVERAGEIF($U$9:$U$308,"Before",O11) -> 9.2721024 | W11: =IFERROR(AVERAGEIF($U$9:$U$308,"During",O11),0) -> 9.2480453 | X11: =(Table1[[#This Row],[Average_During]]-Table1[[#This Row],[Average_Before]])/Table1[[#This Row],[Average_Before]]*100 -> -0.25945698
A12: SP279 | B12: Twitter | C12: 45676 | D12: Story | E12: New music just dropped. Hit play! | F12: 3507 | G12: 295 | H12: 371 | I12: 20410 | J12: 53965 | K12: 212 | L12: #SoundtrackOfLife | M12: #NowPlaying | N12: ChillVibes | O12: =((Posts!$F5+Posts!$G5+Posts!$H5)/Posts!$I5)*100 -> 12.157141 | P12: =SUM(Table2[[#This Row],[Likes]],Table2[[#This Row],[Shares]],Table2[[#This Row],[Comments]]) -> 2647 | Q12: =_xlfn.IFS( Table2[[#This Row],[Campaign_Name]]="SummerBeats", 175000, Table2[[#This Row],[Campaign_Name]]="Wrapped2024", 225000, Table2[[#This Row],[Campaign_Name]]="ChillVibes", 200000, Table2[[#This Row],[Campaign_Name]]="IndieWave", 160000 ) -> 160000 | R12: =Table2[[#This Row],[Net_Engagement]]/Table2[[#This Row],[Total_Budget]] -> 0.01654375 | S12: =_xlfn.IFS( Table2[[#This Row],[Campaign_Name]]="SummerBeats", DATE(2024,6,15), Table2[[#This Row],[Campaign_Name]]="Wrapped2024", DATE(2024,12,1), Table2[[#This Row],[Campaign_Name]]="ChillVibes", DATE(2025,1,10), Table2[[#This Row],[Campaign_Name]]="IndieWave", DATE(2025,3,1) ) -> 45717 | T12: =_xlfn.IFS( Table2[[#This Row],[Campaign_Name]]="SummerBeats", DATE(2024,7,15), Table2[[#This Row],[Campaign_Name]]="Wrapped2024", DATE(2024,12,31), Table2[[#This Row],[Campaign_Name]]="ChillVibes", DATE(2025,2,10), Table2[[#This Row],[Campaign_Name]]="IndieWave", DATE(2025,3,31) ) -> 45747 | U12: =IF(AND(C12>=$S$9,C12<=$T$9),"During","Before") -> During | V12: =AVERAGEIF($U$9:$U$308,"Before",O12) -> 9.2567134 | W12: =IFERROR(AVERAGEIF($U$9:$U$308,"During",O12),0) -> 9.5415158 | X12: =(Table1[[#This Row],[Average_During]]-Table1[[#This Row],[Average_Before]])/Table1[[#This Row],[Average_Before]]*100 -> 3.0767117
A13: SP050 | B13: Twitter | C13: 45769 | D13: Text | E13: Discover fresh beats on Spotify! | F13: 4401 | G13: 421 | H13: 216 | I13: 24890 | J13: 54361 | K13: 148 | L13: #NowPlaying | M13: NA | N13: ChillVibes | O13: =((Posts!$F6+Posts!$G6+Posts!$H6)/Posts!$I6)*100 -> 13.147002 | P13: =SUM(Table2[[#This Row],[Likes]],Table2[[#This Row],[Shares]],Table2[[#This Row],[Comments]]) -> 2082 | Q13: =_xlfn.IFS( Table2[[#This Row],[Campaign_Name]]="SummerBeats", 175000, Table2[[#This Row],[Campaign_Name]]="Wrapped2024", 225000, Table2[[#This Row],[Campaign_Name]]="ChillVibes", 200000, Table2[[#This Row],[Campaign_Name]]="IndieWave", 160000 ) -> 200000 | R13: =Table2[[#This Row],[Net_Engagement]]/Table2[[#This Row],[Total_Budget]] -> 0.01041 | S13: =_xlfn.IFS( Table2[[#This Row],[Campaign_Name]]="SummerBeats", DATE(2024,6,15), Table2[[#This Row],[Campaign_Name]]="Wrapped2024", DATE(2024,12,1), Table2[[#This Row],[Campaign_Name]]="ChillVibes", DATE(2025,1,10), Table2[[#This Row],[Campaign_Name]]="IndieWave", DATE(2025,3,1) ) -> 45667 | T13: =_xlfn.IFS( Table2[[#This Row],[Campaign_Name]]="SummerBeats", DATE(2024,7,15), Table2[[#This Row],[Campaign_Name]]="Wrapped2024", DATE(2024,12,31), Table2[[#This Row],[Campaign_Name]]="ChillVibes", DATE(2025,2,10), Table2[[#This Row],[Campaign_Name]]="IndieWave", DATE(2025,3,31) ) -> 45698 | U13: =IF(AND(C13>=$S$9,C13<=$T$9),"During","Before") -> Before | V13: =AVERAGEIF($U$9:$U$308,"Before",O13) -> 9.2200418 | W13: =IFERROR(AVERAGEIF($U$9:$U$308,"During",O13),0) -> 9.8664063 | X13: =(Table1[[#This Row],[Average_During]]-Table1[[#This Row],[Average_Before]])/Table1[[#This Row],[Average_Before]]*100 -> 7.0104291
A14: SP022 | B14: Instagram | C14: 45823 | D14: Text | E14: Whatâ€™s your vibe today? #SpotifyHits | F14: 4896 | G14: 466 | H14: 233 | I14: 28621 | J14: 34270 | K14: 84 | L14: #SoundtrackOfLife | M14: #NowPlaying | N14: ChillVibes | O14: =((Posts!$F7+Posts!$G7+Posts!$H7)/Posts!$I7)*100 -> 7.4828079 | P14: =SUM(Table2[[#This Row],[Likes]],Table2[[#This Row],[Shares]],Table2[[#This Row],[Comments]]) -> 4336 | Q14: =_xlfn.IFS( Table2[[#This Row],[Campaign_Name]]="SummerBeats", 175000, Table2[[#This Row],[Campaign_Name]]="Wrapped2024", 225000, Table2[[#This Row],[Campaign_Name]]="ChillVibes", 200000, Table2[[#This Row],[Campaign_Name]]="IndieWave", 160000 ) -> 200000 | R14: =Table2[[#This Row],[Net_Engagement]]/Table2[[#This Row],[Total_Budget]] -> 0.02168 | S14: =_xlfn.IFS( Table2[[#This Row],[Campaign_Name]]="SummerBeats", DATE(2024,6,15), Table2[[#This Row],[Campaign_Name]]="Wrapped2024", DATE(2024,12,1), Table2[[#This Row],[Campaign_Name]]="ChillVibes", DATE(2025,1,10), Table2[[#This Row],[Campaign_Name]]="IndieWave", DATE(2025,3,1) ) -> 45667 | T14: =_xlfn.IFS( Table2[[#This Row],[Campaign_Name]]="SummerBeats", DATE(2024,7,15), Table2[[#This Row],[Campaign_Name]]="Wrapped2024", DATE(2024,12,31), Table2[[#This Row],[Campaign_Name]]="ChillVibes", DATE(2025,2,10), Table2[[#This Row],[Campaign_Name]]="IndieWave", DATE(2025,3,31) ) -> 45698 | U14: =IF(AND(C14>=$S$9,C14<=$T$9),"During","Before") -> Before | V14: =AVERAGEIF($U$9:$U$308,"Before",O14) -> 9.2603179 | W14: =IFERROR(AVERAGEIF($U$9:$U$308,"During",O14),0) -> 9.1881179 | X14: =(Table1[[#This Row],[Average_During]]-Table1[[#This Row],[Average_Before]])/Table1[[#This Row],[Average_Before]]*100 -> -0.77967164
A15: SP157 | B15: YouTube | C15: 45718 | D15: Text | E15: From pop to podcasts, itâ€™s all here. | F15: 4425 | G15: 185 | H15: 162 | I15: 24610 | J15: 21342 | K15: 158 | L15: #DiscoverWeekly | M15: #SpotifyWrapped | N15: IndieWave | O15: =((Posts!$F8+Posts!$G8+Posts!$H8)/Posts!$I8)*100 -> 26.064752 | P15: =SUM(Table2[[#This Row],[Likes]],Table2[[#This Row],[Shares]],Table2[[#This Row],[Comments]]) -> 3122 | Q15: =_xlfn.IFS( Table2[[#This Row],[Campaign_Name]]="SummerBeats", 175000, Table2[[#This Row],[Campaign_Name]]="Wrapped2024", 225000, Table2[[#This Row],[Campaign_Name]]="ChillVibes", 200000, Table2[[#This Row],[Campaign_Name]]="IndieWave", 160000 ) -> 200000 | R15: =Table2[[#This Row],[Net_Engagement]]/Table2[[#This Row],[Total_Budget]] -> 0.01561 | S15: =_xlfn.IFS( Table2[[#This Row],[Campaign_Name]]="SummerBeats", DATE(2024,6,15), Table2[[#This Row],[Campaign_Name]]="Wrapped2024", DATE(2024,12,1), Table2[[#This Row],[Campaign_Name]]="ChillVibes", DATE(2025,1,10), Table2[[#This Row],[Campaign_Name]]="IndieWave", DATE(2025,3,1) ) -> 45667 | T15: =_xlfn.IFS( Table2[[#This Row],[Campaign_Name]]="SummerBeats", DATE(2024,7,15), Table2[[#This Row],[Campaign_Name]]="Wrapped2024", DATE(2024,12,31), Table2[[#This Row],[Campaign_Name]]="ChillVibes", DATE(2025,2,10), Table2[[#This Row],[Campaign_Name]]="IndieWave", DATE(2025,3,31) ) -> 45698 | U15: =IF(AND(C15>=$S$9,C15<=$T$9),"During","Before") -> Before | V15: =AVERAGEIF($U$9:$U$308,"Before",O15) -> 9.2375163 | W15: =IFERROR(AVERAGEIF($U$9:$U$308,"During",O15),0) -> 9.5508246 | X15: =(Table1[[#This Row],[Average_During]]-Table1[[#This Row],[Average_Before]])/Table1[[#This Row],[Average_Before]]*100 -> 3.3916934
A16: SP248 | B16: YouTube | C16: 45457 | D16: Reel | E16: Wrapped is here! Relive your top tracks ðŸŽ§ | F16: 4722 | G16: 310 | H16: 344 | I16: 27911 | J16: 19000 | K16: 225 | L16: #DiscoverWeekly | M16: #SoundtrackOfLife | N16: SummerBeats | O16: =((Posts!$F9+Posts!$G9+Posts!$H9)/Posts!$I9)*100 -> 8.7100435 | P16: =SUM(Table2[[#This Row],[Likes]],Table2[[#This Row],[Shares]],Table2[[#This Row],[Comments]]) -> 4227 | Q16: =_xlfn.IFS( Table2[[#This Row],[Campaign_Name]]="SummerBeats", 175000, Table2[[#This Row],[Campaign_Name]]="Wrapped2024", 225000, Table2[[#This Row],[Campaign_Name]]="ChillVibes", 200000, Table2[[#This Row],[Campaign_Name]]="IndieWave", 160000 ) -> 200000 | R16: =Table2[[#This Row],[Net_Engagement]]/Table2[[#This Row],[Total_Budget]] -> 0.021135 | S16: =_xlfn.IFS( Table2[[#This Row],[Campaign_Name]]="SummerBeats", DATE(2024,6,15), Table2[[#This Row],[Campaign_Name]]="Wrapped2024", DATE(2024,12,1), Table2[[#This Row],[Campaign_Name]]="ChillVibes", DATE(2025,1,10), Table2[[#This Row],[Campaign_Name]]="IndieWave", DATE(2025,3,1) ) -> 45667 | T16: =_xlfn.IFS( Table2[[#This Row],[Campaign_Name]]="SummerBeats", DATE(2024,7,15), Table2[[#This Row],[Campaign_Name]]="Wrapped2024", DATE(2024,12,31), Table2[[#This Row],[Campaign_Name]]="ChillVibes", DATE(2025,2,10), Table2[[#This Row],[Campaign_Name]]="IndieWave", DATE(2025,3,31) ) -> 45698 | U16: =IF(AND(C16>=$S$9,C16<=$T$9),"During","Before") -> Before | V16: =AVERAGEIF($U$9:$U$308,"Before",O16) -> 9.2423218 | W16: =IFERROR(AVERAGEIF($U$9:$U$308,"During",O16),0) -> 8.7267562 | X16: =(Table1[[#This Row],[Average_During]]-Table1[[#This Row],[Average_Before]])/Table1[[#This Row],[Average_Before]]*100 -> -5.5783125
A17: SP136 | B17: Twitter | C17: 45615 | D17: Text | E17: Top trending tracks updated daily! | F17: 3728 | G17: 271 | H17: 275 | I17: 22827 | J17: 37034 | K17: 199 | L17: #NowPlaying | M17: NA | N17: ChillVibes | O17: =((Posts!$F10+Posts!$G10+Posts!$H10)/Posts!$I10)*100 -> 8.3943337 | P17: =SUM(Table2[[#This Row],[Likes]],Table2[[#This Row],[Shares]],Table2[[#This Row],[Comments]]) -> 4520 | Q17: =_xlfn.IFS( Table2[[#This Row],[Campaign_Name]]="SummerBeats", 175000, Table2[[#This Row],[Campaign_Name]]="Wrapped2024", 225000, Table2[[#This Row],[Campaign_Name]]="ChillVibes", 200000, Table2[[#This Row],[Campaign_Name]]="IndieWave", 160000 ) -> 200000 | R17: =Table2[[#This Row],[Net_Engagement]]/Table2[[#This Row],[Total_Budget]] -> 0.0226 | S17: =_xlfn.IFS( Table2[[#This Row],[Campaign_Name]]="SummerBeats", DATE(2024,6,15), Table2[[#This Row],[Campaign_Name]]="Wrapped2024", DATE(2024,12,1), Table2[[#This Row],[Campaign_Name]]="ChillVibes", DATE(2025,1,10), Table2[[#This Row],[Campaign_Name]]="IndieWave", DATE(2025,3,1) ) -> 45667 | T17: =_xlfn.IFS( Table2[[#This Row],[Campaign_Name]]="SummerBeats", DATE(2024,7,15), Table2[[#This Row],[Campaign_Name]]="Wrapped2024", DATE(2024,12,31), Table2[[#This Row],[Campaign_Name]]="ChillVibes", DATE(2025,2,10), Table2[[#This Row],[Campaign_Name]]="IndieWave", DATE(2025,3,31) ) -> 45698 | U17: =IF(AND(C17>=$S$9,C17<=$T$9),"During","Before") -> Before | V17: =AVERAGEIF($U$9:$U$308,"Before",O17) -> 9.235741 | W17: =IFERROR(AVERAGEIF($U$9:$U$308,"During",O17),0) -> 8.8317149 | X17: =(Table1[[#This Row],[Average_During]]-Table1[[#This Row],[Average_Before]])/Table1[[#This Row],[Average_Before]]*100 -> -4.3745933
A18: SP068 | B18: Twitter | C18: 45379 | D18: Text | E18: Music that moves youâ€”only on Spotify. | F18: 3276 | G18: 421 | H18: 114 | I18: 20580 | J18: 30324 | K18: 221 | L18: #SoundtrackOfLife | M18: NA | N18: IndieWave | O18: =((Posts!$F11+Posts!$G11+Posts!$H11)/Posts!$I11)*100 -> 12.997311 | P18: =SUM(Table2[[#This Row],[Likes]],Table2[[#This Row],[Shares]],Table2[[#This Row],[Comments]]) -> 1953 | Q18: =_xlfn.IFS( Table2[[#This Row],[Campaign_Name]]="SummerBeats", 175000, Table2[[#This Row],[Campaign_Name]]="Wrapped2024", 225000, Table2[[#This Row],[Campaign_Name]]="ChillVibes", 200000, Table2[[#This Row],[Campaign_Name]]="IndieWave", 160000 ) -> 200000 | R18: =Table2[[#This Row],[Net_Engagement]]/Table2[[#This Row],[Total_Budget]] -> 0.009765 | S18: =_xlfn.IFS( Table2[[#This Row],[Campaign_Name]]="SummerBeats", DATE(2024,6,15), Table2[[#This Row],[Campaign_Name]]="Wrapped2024", DATE(2024,12,1), Table2[[#This Row],[Campaign_Name]]="ChillVibes", DATE(2025,1,10), Table2[[#This Row],[Campaign_Name]]="IndieWave", DATE(2025,3,1) ) -> 45667 | T18: =_xlfn.IFS( Table2[[#This Row],[Campaign_Name]]="SummerBeats", DATE(2024,7,15), Table2[[#This Row],[Campaign_Name]]="Wrapped2024", DATE(2024,12,31), Table2[[#This Row],[Campaign_Name]]="ChillVibes", DATE(2025,2,10), Table2[[#This Row],[Campaign_Name]]="IndieWave", DATE(2025,3,31) ) -> 45698 | U18: =IF(AND(C18>=$S$9,C18<=$T$9),"During","Before") -> Before | V18: =AVERAGEIF($U$9:$U$308,"Before",O18) -> 9.1628811 | W18: =IFERROR(AVERAGEIF($U$9:$U$308,"During",O18),0) -> 9.7608377 | X18: =(Table1[[#This Row],[Average_During]]-Table1[[#This Row],[Average_Before]])/Table1[[#This Row],[Average_Before]]*100 -> 6.5258578
A19: SP088 | B19: Twitter | C19: 45705 | D19: Story | E19: Whatâ€™s your vibe today? #SpotifyHits | F19: 4796 | G19: 427 | H19: 339 | I19: 30752 | J19: 33870 | K19: 298 | L19: #SoundtrackOfLife | M19: #NowPlaying | N19: ChillVibes | O19: =((Posts!$F12+Posts!$G12+Posts!$H12)/Posts!$I12)*100 -> 8.4525482 | P19: =SUM(Table2[[#This Row],[Likes]],Table2[[#This Row],[Shares]],Table2[[#This Row],[Comments]]) -> 4545 | Q19: =_xlfn.IFS( Table2[[#This Row],[Campaign_Name]]="SummerBeats", 175000, Table2[[#This Row],[Campaign_Name]]="Wrapped2024", 225000, Table2[[#This Row],[Campaign_Name]]="ChillVibes", 200000, Table2[[#This Row],[Campaign_Name]]="IndieWave", 160000 ) -> 225000 | R19: =Table2[[#This Row],[Net_Engagement]]/Table2[[#This Row],[Total_Budget]] -> 0.0202 | S19: =_xlfn.IFS( Table2[[#This Row],[Campaign_Name]]="SummerBeats", DATE(2024,6,15), Table2[[#This Row],[Campaign_Name]]="Wrapped2024", DATE(2024,12,1), Table2[[#This Row],[Campaign_Name]]="ChillVibes", DATE(2025,1,10), Table2[[#This Row],[Campaign_Name]]="IndieWave", DATE(2025,3,1) ) -> 45627 | T19: =_xlfn.IFS( Table2[[#This Row],[Campaign_Name]]="SummerBeats", DATE(2024,7,15), Table2[[#This Row],[Campaign_Name]]="Wrapped2024", DATE(2024,12,31), Table2[[#This Row],[Campaign_Name]]="ChillVibes", DATE(2025,2,10), Table2[[#This Row],[Campaign_Name]]="IndieWave", DATE(2025,3,31) ) -> 45657 | U19: =IF(AND(C19>=$S$9,C19<=$T$9),"During","Before") -> Before | V19: =AVERAGEIF($U$9:$U$308,"Before",O19) -> 9.3094867 | W19: =IFERROR(AVERAGEIF($U$9:$U$308,"During",O19),0) -> 7.800623 | X19: =(Table1[[#This Row],[Average_During]]-Table1[[#This Row],[Average_Before]])/Table1[[#This Row],[Average_Before]]*100 -> -16.207808
A20: SP213 | B20: Instagram | C20: 45832 | D20: Story | E20: Get into the groove with our new drop! | F20: 4902 | G20: 422 | H20: 376 | I20: 31674 | J20: 53225 | K20: 147 | L20: #NowPlaying | M20: NA | N20: Wrapped2024 | O20: =((Posts!$F13+Posts!$G13+Posts!$H13)/Posts!$I13)*100 -> 5.4191936 | P20: =SUM(Table2[[#This Row],[Likes]],Table2[[#This Row],[Shares]],Table2[[#This Row],[Comments]]) -> 2045 | Q20: =_xlfn.IFS( Table2[[#This Row],[Campaign_Name]]="SummerBeats", 175000, Table2[[#This Row],[Campaign_Name]]="Wrapped2024", 225000, Table2[[#This Row],[Campaign_Name]]="ChillVibes", 200000, Table2[[#This Row],[Campaign_Name]]="IndieWave", 160000 ) -> 175000 | R20: =Table2[[#This Row],[Net_Engagement]]/Table2[[#This Row],[Total_Budget]] -> 0.011685714 | S20: =_xlfn.IFS( Table2[[#This Row],[Campaign_Name]]="SummerBeats", DATE(2024,6,15), Table2[[#This Row],[Campaign_Name]]="Wrapped2024", DATE(2024,12,1), Table2[[#This Row],[Campaign_Name]]="ChillVibes", DATE(2025,1,10), Table2[[#This Row],[Campaign_Name]]="IndieWave", DATE(2025,3,1) ) -> 45458 | T20: =_xlfn.IFS( Table2[[#This Row],[Campaign_Name]]="SummerBeats", DATE(2024,7,15), Table2[[#This Row],[Campaign_Name]]="Wrapped2024", DATE(2024,12,31), Table2[[#This Row],[Campaign_Name]]="ChillVibes", DATE(2025,2,10), Table2[[#This Row],[Campaign_Name]]="IndieWave", DATE(2025,3,31) ) -> 45488 | U20: =IF(AND(C20>=$S$9,C20<=$T$9),"During","Before") -> Before | V20: =AVERAGEIF($U$9:$U$308,"Before",O20) -> 9.1876069 | W20: =IFERROR(AVERAGEIF($U$9:$U$308,"During",O20),0) -> 9.3249979 | X20: =(Table1[[#This Row],[Average_During]]-Table1[[#This Row],[Average_Before]])/Table1[[#This Row],[Average_Before]]*100 -> 1.4953955
... A308: SP059 | B308: YouTube | C308: 45514 | D308: Text | E308: From pop to podcasts, itâ€™s all here. | F308: 1105 | G308: 181 | H308: 55 | I308: 53581 | J308: 74048 | K308: 220 | L308: #DiscoverWeekly | M308: #SpotifyWrapped | N308: IndieWave | O308: =((Posts!$F301+Posts!$G301+Posts!$H301)/Posts!$I301)*100 -> 9.4300914 | P308: =SUM(Table2[[#This Row],[Likes]],Table2[[#This Row],[Shares]],Table2[[#This Row],[Comments]]) -> #VALUE! | Q308: =_xlfn.IFS( Table2[[#This Row],[Campaign_Name]]="SummerBeats", 175000, Table2[[#This Row],[Campaign_Name]]="Wrapped2024", 225000, Table2[[#This Row],[Campaign_Name]]="ChillVibes", 200000, Table2[[#This Row],[Campaign_Name]]="IndieWave", 160000 ) -> #VALUE! | R308: =Table2[[#This Row],[Net_Engagement]]/Table2[[#This Row],[Total_Budget]] -> #VALUE! | S308: =_xlfn.IFS( Table2[[#This Row],[Campaign_Name]]="SummerBeats", DATE(2024,6,15), Table2[[#This Row],[Campaign_Name]]="Wrapped2024", DATE(2024,12,1), Table2[[#This Row],[Campaign_Name]]="ChillVibes", DATE(2025,1,10), Table2[[#This Row],[Campaign_Name]]="IndieWave", DATE(2025,3,1) ) -> #VALUE! | T308: =_xlfn.IFS( Table2[[#This Row],[Campaign_Name]]="SummerBeats", DATE(2024,7,15), Table2[[#This Row],[Campaign_Name]]="Wrapped2024", DATE(2024,12,31), Table2[[#This Row],[Campaign_Name]]="ChillVibes", DATE(2025,2,10), Table2[[#This Row],[Campaign_Name]]="IndieWave", DATE(2025,3,31) ) -> #VALUE! | U308: =IF(AND(C308>=$S$9,C308<=$T$9),"During","Before") -> Before | V308: =AVERAGEIF($U$9:$U$308,"Before",O308) -> 9.4300914 | W308: =IFERROR(AVERAGEIF($U$9:$U$308,"During",O308),0) -> 0 | X308: =(Table1[[#This Row],[Average_During]]-Table1[[#This Row],[Average_Before]])/Table1[[#This Row],[Average_Before]]*100 -> -100

Sheet Task2
A1: Post ID | B1: Platform | C1: Date | D1: Content Type | E1: Post Text | F1: Likes | G1: Shares | H1: Comments | I1: Impressions | J1: Reach | K1: Clicks | L1: Hashtags Used | M1: Campaign_Name | N1: Engagement_Rate
A2: SP007 | B2: Twitter | C2: 45645 | D2: Story | E2: Get into the groove with our new drop! | F2: 4674 | G2: 409 | H2: 327 | I2: 20756 | J2: 63599 | K2: 212 | L2: #SoundtrackOfLife,#NowPlaying | M2: ChillVibes | N2: =((F2+G2+H2)/I2)*100 -> 26.064752
A3: SP106 | B3: Twitter | C3: 45677 | D3: Story | E3: New music just dropped. Hit play! | F3: 4619 | G3: 272 | H3: 57 | I3: 21334 | J3: 46292 | K3: 91 | L3: #SoundtrackOfLife,#NowPlaying | M3: ChillVibes | N3: =((F3+G3+H3)/I3)*100 -> 23.193025
A4: SP186 | B4: Twitter | C4: 45459 | D4: Story | E4: Explore the latest podcasts now. | F4: 4618 | G4: 312 | H4: 254 | I4: 22571 | J4: 29453 | K4: 197 | L4: #MusicForEveryone,#NowPlaying | M4: ChillVibes | N4: =((F4+G4+H4)/I4)*100 -> 22.967525
A5: SP279 | B5: Twitter | C5: 45676 | D5: Story | E5: New music just dropped. Hit play! | F5: 3507 | G5: 295 | H5: 371 | I5: 20410 | J5: 53965 | K5: 212 | L5: #SoundtrackOfLife,#NowPlaying | M5: ChillVibes | N5: =((F5+G5+H5)/I5)*100 -> 20.44586
A6: SP050 | B6: Twitter | C6: 45769 | D6: Text | E6: Discover fresh beats on Spotify! | F6: 4401 | G6: 421 | H6: 216 | I6: 24890 | J6: 54361 | K6: 148 | L6: #NowPlaying | M6: ChillVibes | N6: =((F6+G6+H6)/I6)*100 -> 20.241061
A7: SP022 | B7: Instagram | C7: 45823 | D7: Text | E7: Whatâ€™s your vibe today? #SpotifyHits | F7: 4896 | G7: 466 | H7: 233 | I7: 28621 | J7: 34270 | K7: 84 | L7: #SoundtrackOfLife,#NowPlaying | M7: ChillVibes | N7: =((F7+G7+H7)/I7)*100 -> 19.548583
A8: SP157 | B8: YouTube | C8: 45718 | D8: Text | E8: From pop to podcasts, itâ€™s all here. | F8: 4425 | G8: 185 | H8: 162 | I8: 24610 | J8: 21342 | K8: 158 | L8: #DiscoverWeekly,#SpotifyWrapped | M8: IndieWave | N8: =((F8+G8+H8)/I8)*100 -> 19.390492
A9: SP248 | B9: YouTube | C9: 45457 | D9: Reel | E9: Wrapped is here! Relive your top tracks ðŸŽ§ | F9: 4722 | G9: 310 | H9: 344 | I9: 27911 | J9: 19000 | K9: 225 | L9: #DiscoverWeekly,#SoundtrackOfLife | M9: SummerBeats | N9: =((F9+G9+H9)/I9)*100 -> 19.261223
A10: SP136 | B10: Twitter | C10: 45615 | D10: Text | E10: Top trending tracks updated daily! | F10: 3728 | G10: 271 | H10: 275 | I10: 22827 | J10: 37034 | K10: 199 | L10: #NowPlaying | M10: ChillVibes | N10: =((F10+G10+H10)/I10)*100 -> 18.723442
A11: SP068 | B11: Twitter | C11: 45379 | D11: Text | E11: Music that moves youâ€”only on Spotify. | F11: 3276 | G11: 421 | H11: 114 | I11: 20580 | J11: 30324 | K11: 221 | L11: #SoundtrackOfLife | M11: IndieWave | N11: =((F11+G11+H11)/I11)*100 -> 18.517979
A12: SP088 | B12: Twitter | C12: 45705 | D12: Story | E12: Whatâ€™s your vibe today? #SpotifyHits | F12: 4796 | G12: 427 | H12: 339 | I12: 30752 | J12: 33870 | K12: 298 | L12: #SoundtrackOfLife,#NowPlaying | M12: ChillVibes | N12: =((F12+G12+H12)/I12)*100 -> 18.086629
A13: SP213 | B13: Instagram | C13: 45832 | D13: Story | E13: Get into the groove with our new drop! | F13: 4902 | G13: 422 | H13: 376 | I13: 31674 | J13: 53225 | K13: 147 | L13: #NowPlaying | M13: Wrapped2024 | N13: =((F13+G13+H13)/I13)*100 -> 17.995833
... A301: SP059 | B301: YouTube | C301: 45514 | D301: Text | E301: From pop to podcasts, itâ€™s all here. | F301: 1105 | G301: 181 | H301: 55 | I301: 53581 | J301: 74048 | K301: 220 | L301: #DiscoverWeekly,#SpotifyWrapped | M301: IndieWave | N301: =((F301+G301+H301)/I301)*100 -> 2.5027528
A310: Row Labels | B310: Sum of Likes | C310: Sum of Shares | D310: Sum of Comments
A311: Instagram | B311: 251473 | C311: 29285 | D311: 20818
A312: Story | B312: 61815 | C312: 7993 | D312: 5656
A313: Text | B313: 189658 | C313: 21292 | D313: 15162
A314: Twitter | B314: 450295 | C314: 45498 | D314: 31577
A315: Story | B315: 272103 | C315: 26494 | D315: 18442
A316: Text | B316: 178192 | C316: 19004 | D316: 13135
A317: YouTube | B317: 195407 | C317: 18618 | D317: 14671
A318: Reel | B318: 89871 | C318: 9086 | D318: 6826
A319: Text | B319: 105536 | C319: 9532 | D319: 7845
A329: Row Labels | B329: Average of Clicks
A330: #SpotifyWrapped | B330: 208.47059
A331: #DiscoverWeekly | B331: 197.16923
A332: #SoundtrackOfLife | B332: 192.45872
A333: #NowPlaying | B333: 186.72028
A334: #MusicForEveryone | B334: 183.47761
A341: Row Labels | B341: Average of Clicks | C341: Ranking
A342: #SpotifyWrapped | B342: 208.47059 | C342: =_xlfn.RANK.EQ(B342,$A$342:$B$346,0) -> 1
A343: #DiscoverWeekly | B343: 197.16923 | C343: =_xlfn.RANK.EQ(B343,$A$342:$B$346,0) -> 2
A344: #SoundtrackOfLife | B344: 192.45872 | C344: =_xlfn.RANK.EQ(B344,$A$342:$B$346,0) -> 3
A345: #NowPlaying | B345: 186.72028 | C345: =_xlfn.RANK.EQ(B345,$A$342:$B$346,0) -> 4
A346: #MusicForEveryone | B346: 183.47761 | C346: =_xlfn.RANK.EQ(B346,$A$342:$B$346,0) -> 5

Sheet Task3
A5: Row Labels | B5: Sum of Likes | C5: Sum of Shares | D5: Sum of Comments | E5: Sum of Engagement_Rate
A6: Twitter | B6: 450295 | C6: 45498 | D6: 31577 | E6: 1421.3122
A7: Instagram | B7: 251473 | C7: 29285 | D7: 20818 | E7: 808.07399
A8: YouTube | B8: 195407 | C8: 18618 | D8: 14671 | E8: 555.08115
A9: Grand Total | B9: 897175 | C9: 93401 | D9: 67066 | E9: 2784.4673
A16: Sum of Net_Followers | B16: Column Labels
A17: Row Labels | B17: Instagram | C17: Twitter | D17: YouTube
A18: 45446 | B18: 1334 | C18: 909 | D18: 1176
A19: 45453 | B19: 928 | C19: 1397 | D19: 452
A20: 45460 | B20: 590 | C20: 1283 | D20: 1302
A21: 45467 | B21: 612 | C21: 1121 | D21: 700
A22: 45474 | B22: 714 | C22: 595 | D22: 1117
A23: 45481 | B23: 667 | C23: 1371 | D23: 1117
A24: 45488 | B24: 359 | C24: 1098 | D24: 912
A25: 45495 | B25: 792 | C25: 364 | D25: 1125
A26: 45502 | B26: 869 | C26: 414 | D26: 849
A27: 45509 | B27: 1353 | C27: 582 | D27: 758
A28: 45516 | B28: 977 | C28: 1191 | D28: 904
A29: 45523 | B29: 909 | C29: 382 | D29: 1009
... A54: 45698 | B54: 915 | C54: 1108 | D54: 338
A55: 45705 | B55: 724 | C55: 463 | D55: 356 | F55: Row Labels | G55: Sum of Ad_Spend | H55: Average of Engagement_Rate
A56: 45712 | B56: 378 | C56: 636 | D56: 699 | F56: Instagram | G56: 1035942 | H56: 6.458209
A57: 45719 | B57: 1279 | C57: 1006 | D57: 478 | F57: Twitter | G57: 1114204 | H57: 6.8856716
A58: 45726 | B58: 545 | C58: 1005 | D58: 765 | F58: YouTube | G58: 1065782 | H58: 6.7189394
A59: 45733 | B59: 564 | C59: 496 | D59: 1128 | F59: Grand Total | G59: 3215928 | H59: 6.68745
A60: 45740 | B60: 565 | C60: 813 | D60: 1301
A61: 45747 | B61: 436 | C61: 978 | D61: 1367
A62: 45754 | B62: 1337 | C62: 1014 | D62: 940
A63: 45761 | B63: 690 | C63: 1335 | D63: 1191
A64: 45768 | B64: 353 | C64: 486 | D64: 889
A65: 45775 | B65: 983 | C65: 581 | D65: 814
A66: 45782 | B66: 919 | C66: 676 | D66: 459
A67: 45789 | B67: 576 | C67: 447 | D67: 377
A68: 45796 | B68: 932 | C68: 1356 | D68: 1281
A69: 45803 | B69: 1041 | C69: 1184 | D69: 684 | F69: Row Labels | G69: Sum of Engagement_Rate | H69: % of Total Engagement
A70: 45810 | B70: 354 | C70: 1126 | D70: 569 | F70: Instagram | G70: 808.07399 | H70: =GETPIVOTDATA("Engagement_Rate",$F$69,"Platform","Instagram")/GETPIVOTDATA("Engagement_Rate",$F$69) -> 0.29020775
A71: 45817 | B71: 730 | C71: 578 | D71: 935 | F71: Twitter | G71: 1421.3122 | H71: =GETPIVOTDATA("Engagement_Rate",$F$69,"Platform","Twitter")/GETPIVOTDATA("Engagement_Rate",$F$69) -> 0.51044312
A72: 45824 | B72: 698 | C72: 325 | D72: 994 | F72: YouTube | G72: 555.08115 | H72: =GETPIVOTDATA("Engagement_Rate",$F$69,"Platform","YouTube")/GETPIVOTDATA("Engagement_Rate",$F$69) -> 0.19934913
A73: 45831 | B73: 320 | C73: 544 | D73: 520 | F73: Grand Total | G73: 2784.4673 | H73: =GETPIVOTDATA("Engagement_Rate",$F$69)/GETPIVOTDATA("Engagement_Rate",$F$69) -> 1
A74: 45838 | B74: 485 | C74: 1234 | D74: 596
...

Sheet Task4
A4: Row Labels | B4: Average of Engagement_Rate | C4: Count of Engagement_Rate
A5: #DiscoverWeekly | B5: 8.7606633 | C5: 130
A6: #MusicForEveryone | B6: 9.4160898 | C6: 33
A7: #NowPlaying | B7: 9.9415714 | C7: 57
A8: #SoundtrackOfLife | B8: 9.6022568 | C8: 80
A9: Grand Total | B9: 9.2815577 | C9: 300
A16: Row Labels | B16: Sum of Top performer
A17: YouTube | B17: 8353
A18: Reel | B18: 4197
A19: Text | B19: 4156
A20: Twitter | B20: 20581
A21: Story | B21: 11505
A22: Text | B22: 9076
A23: Instagram | B23: 14137
A24: Story | B24: 4092
A25: Text | B25: 10045
A26: Grand Total | B26: 43071
A31: Row Labels | B31: Count of Platform
A32: Twitter | B32: 148
A33: Instagram | B33: 89
A34: YouTube | B34: 63
A35: Grand Total | B35: 300

Sheet Task5
A5: Average impressions, likes, clicks per campaign
A6: Row Labels | B6: Average of Clicks | C6: Average of Impressions | D6: Average of Likes
A7: ChillVibes | B7: 186.41558 | C7: 41116.026 | D7: 3058.6623
A8: IndieWave | B8: 199.11702 | C8: 42971.33 | D8: 2919.734
A9: SummerBeats | B9: 191.62069 | C9: 42546.655 | D9: 3099
A10: Wrapped2024 | B10: 200.6087 | C10: 37626.348 | D10: 2687.6087
A11: Grand Total | B11: 191.98667 | C11: 41568.107 | D11: 2990.5833
A13: Total impressions, likes, clicks per campaign
A14: Row Labels | B14: Sum of Impressions | C14: Sum of Clicks | D14: Sum of Likes
A15: ChillVibes | B15: 6331868 | C15: 28708 | D15: 471034
A16: IndieWave | B16: 4039305 | C16: 18717 | D16: 274455
A17: SummerBeats | B17: 1233853 | C17: 5557 | D17: 89871
A18: Wrapped2024 | B18: 865406 | C18: 4614 | D18: 61815
A19: Grand Total | B19: 12470432 | C19: 57596 | D19: 897175
A25: Row Labels | B25: Sum of Average-Before | C25: Sum of Average_During | D25: Sum of Uplift
A26: ChillVibes | B26: 1370.22 | C26: 1398.1394 | D26: 1.0505093
A27: IndieWave | B27: 835.37102 | C27: 832.62263 | D27: 0.059384795
A28: SummerBeats | B28: 256.78481 | C28: 255.86184 | D28: -0.024268817
A29: Wrapped2024 | B29: 206.23341 | C29: 203.14018 | D29: -0.08562529
A30: Grand Total | B30: 2668.6093 | C30: 2689.7641 | D30: 1
A58: Row Labels | B58: Sum of ROI
A59: ChillVibes | B59: 2.8103603
A60: IndieWave | B60: 1.9340846
A61: SummerBeats | B61: 0.53677006
A62: Wrapped2024 | B62: 0.4461374
A63: Grand Total | B63: 5.7273523

Sheet Task6
A4: Row Labels | B4: Sum of Net_Followers
A5: 4-Nov | B5: 3576
A6: 19-May | B6: 3569
A7: 3-Jun | B7: 3419
A8: 7-Apr | B8: 3291
A9: 28-Jul | B9: 3236
A10: 14-Apr | B10: 3216
A11: 17-Jun | B11: 3175
A12: 8-Jul | B12: 3155
A13: 30-Sep | B13: 3151
A14: 12-Aug | B14: 3072
A15: 26-May | B15: 2909
A16: 11-Nov | B16: 2794
... A36: 1-Jul | B36: 2426
A37: 2-Dec | B37: 2383 | F37: Row Labels | G37: Sum of Ad_Spend | H37: Sum of Total_Followers
A38: 28-Apr | B38: 2378 | F38: -0.01691599 | G38: 3215928 | H38: 46501807
A39: 15-Jul | B39: 2369 | F39: Grand Total | G39: 3215928 | H39: 46501807
A40: 10-Feb | B40: 2361
A41: 11-Aug | B41: 2347
A42: 13-Jan | B42: 2341
A43: 7-Oct | B43: 2338
A44: 30-Dec | B44: 2337
A45: 30-Jun | B45: 2315
A46: 10-Mar | B46: 2315
A47: 19-Aug | B47: 2300
A48: 25-Nov | B48: 2287
A49: 22-Jul | B49: 2281
A50: 9-Jun | B50: 2243
A51: 17-Mar | B51: 2188
... A72: Grand Total | B72: 161588

Sheet Detail1
A1: Details for Sum of Total_Followers
A3: Week_Start_Date | B3: Platform | C3: New_Followers | D3: Unfollows | E3: Total_Followers | F3: Engagement_Rate | G3: Ad_Spend | H3: Net_Followers | I3: Corelation
A4: 45810 | B4: YouTube | C4: 637 | D4: 68 | E4: 115694 | F4: 9.99 | G4: 12562 | H4: 569 | I4: -0.01691599
A5: 45845 | B5: Instagram | C5: 974 | D5: 143 | E5: 247965 | F5: 9.98 | G5: 12767 | H5: 831 | I5: -0.01691599
A6: 45453 | B6: YouTube | C6: 545 | D6: 93 | E6: 391621 | F6: 9.96 | G6: 22029 | H6: 452 | I6: -0.01691599
A7: 45845 | B7: Twitter | C7: 1155 | D7: 122 | E7: 387352 | F7: 9.93 | G7: 12170 | H7: 1033 | I7: -0.01691599
A8: 45446 | B8: Instagram | C8: 1402 | D8: 68 | E8: 124562 | F8: 9.92 | G8: 23125 | H8: 1334 | I8: -0.01691599
A9: 45509 | B9: Instagram | C9: 1449 | D9: 96 | E9: 200636 | F9: 9.92 | G9: 15613 | H9: 1353 | I9: -0.01691599
A10: 45600 | B10: Twitter | C10: 1463 | D10: 73 | E10: 348877 | F10: 9.91 | G10: 26273 | H10: 1390 | I10: -0.01691599
A11: 45684 | B11: Instagram | C11: 566 | D11: 225 | E11: 368984 | F11: 9.82 | G11: 9592 | H11: 341 | I11: -0.01691599
A12: 45747 | B12: Twitter | C12: 1232 | D12: 254 | E12: 107718 | F12: 9.71 | G12: 13740 | H12: 978 | I12: -0.01691599
A13: 45621 | B13: YouTube | C13: 1313 | D13: 159 | E13: 197183 | F13: 9.71 | G13: 6625 | H13: 1154 | I13: -0.01691599
A14: 45467 | B14: YouTube | C14: 844 | D14: 144 | E14: 126015 | F14: 9.65 | G14: 22456 | H14: 700 | I14: -0.01691599
A15: 45852 | B15: Twitter | C15: 670 | D15: 242 | E15: 281913 | F15: 9.62 | G15: 16377 | H15: 428 | I15: -0.01691599
... A203: 45894 | B203: YouTube | C203: 791 | D203: 273 | E203: 144049 | F203: 3.08 | G203: 5281 | H203: 518 | I203: -0.01691599

Sheet Posts
A1: Post ID | B1: Platform | C1: Date | D1: Content Type | E1: Post Text | F1: Likes | G1: Shares | H1: Comments | I1: Impressions | J1: Reach | K1: Clicks | L1: Hashtags Used | M1: Campaign_Name | N1: Engagement_Rate | O1: Net_Engagement | P1: Total_Budget | Q1: ROI | R1: Start_Date | S1: End_Date
A2: SP001 | B2: Instagram | C2: 45781 | D2: Text | E2: Discover fresh beats on Spotify! | F2: 2414 | G2: 245 | H2: 137 | I2: 21181 | J2: 45292 | K2: 133 | L2: #SoundtrackOfLife,#NowPlaying | M2: ChillVibes | N2: =((F2+G2+H2)/I2)*100 -> 13.20051 | O2: =SUM(Table2[[#This Row],[Likes]],Table2[[#This Row],[Shares]],Table2[[#This Row],[Comments]]) -> 2796 | P2: =_xlfn.IFS( Table2[[#This Row],[Campaign_Name]]="SummerBeats", 175000, Table2[[#This Row],[Campaign_Name]]="Wrapped2024", 225000, Table2[[#This Row],[Campaign_Name]]="ChillVibes", 200000, Table2[[#This Row],[Campaign_Name]]="IndieWave", 160000 ) -> 200000 | Q2: =Table2[[#This Row],[Net_Engagement]]/Table2[[#This Row],[Total_Budget]] -> 0.01398 | R2: =_xlfn.IFS( Table2[[#This Row],[Campaign_Name]]="SummerBeats", DATE(2024,6,15), Table2[[#This Row],[Campaign_Name]]="Wrapped2024", DATE(2024,12,1), Table2[[#This Row],[Campaign_Name]]="ChillVibes", DATE(2025,1,10), Table2[[#This Row],[Campaign_Name]]="IndieWave", DATE(2025,3,1) ) -> 45667 | S2: =_xlfn.IFS( Table2[[#This Row],[Campaign_Name]]="SummerBeats", DATE(2024,7,15), Table2[[#This Row],[Campaign_Name]]="Wrapped2024", DATE(2024,12,31), Table2[[#This Row],[Campaign_Name]]="ChillVibes", DATE(2025,2,10), Table2[[#This Row],[Campaign_Name]]="IndieWave", DATE(2025,3,31) ) -> 45698
A3: SP002 | B3: Instagram | C3: 45689 | D3: Text | E3: Explore the latest podcasts now. | F3: 1934 | G3: 210 | H3: 393 | I3: 29129 | J3: 73287 | K3: 273 | L3: #DiscoverWeekly | M3: IndieWave | N3: =((F3+G3+H3)/I3)*100 -> 8.7095335 | O3: =SUM(Table2[[#This Row],[Likes]],Table2[[#This Row],[Shares]],Table2[[#This Row],[Comments]]) -> 2537 | P3: =_xlfn.IFS( Table2[[#This Row],[Campaign_Name]]="SummerBeats", 175000, Table2[[#This Row],[Campaign_Name]]="Wrapped2024", 225000, Table2[[#This Row],[Campaign_Name]]="ChillVibes", 200000, Table2[[#This Row],[Campaign_Name]]="IndieWave", 160000 ) -> 160000 | Q3: =Table2[[#This Row],[Net_Engagement]]/Table2[[#This Row],[Total_Budget]] -> 0.01585625 | R3: =_xlfn.IFS( Table2[[#This Row],[Campaign_Name]]="SummerBeats", DATE(2024,6,15), Table2[[#This Row],[Campaign_Name]]="Wrapped2024", DATE(2024,12,1), Table2[[#This Row],[Campaign_Name]]="ChillVibes", DATE(2025,1,10), Table2[[#This Row],[Campaign_Name]]="IndieWave", DATE(2025,3,1) ) -> 45717 | S3: =_xlfn.IFS( Table2[[#This Row],[Campaign_Name]]="SummerBeats", DATE(2024,7,15), Table2[[#This Row],[Campaign_Name]]="Wrapped2024", DATE(2024,12,31), Table2[[#This Row],[Campaign_Name]]="ChillVibes", DATE(2025,2,10), Table2[[#This Row],[Campaign_Name]]="IndieWave", DATE(2025,3,31) ) -> 45747
A4: SP003 | B4: Twitter | C4: 45629 | D4: Story | E4: New music just dropped. Hit play! | F4: 3092 | G4: 177 | H4: 81 | I4: 47533 | J4: 29220 | K4: 121 | L4: #MusicForEveryone,#NowPlaying | M4: ChillVibes | N4: =((F4+G4+H4)/I4)*100 -> 7.0477353 | O4: =SUM(Table2[[#This Row],[Likes]],Table2[[#This Row],[Shares]],Table2[[#This Row],[Comments]]) -> 3350 | P4: =_xlfn.IFS( Table2[[#This Row],[Campaign_Name]]="SummerBeats", 175000, Table2[[#This Row],[Campaign_Name]]="Wrapped2024", 225000, Table2[[#This Row],[Campaign_Name]]="ChillVibes", 200000, Table2[[#This Row],[Campaign_Name]]="IndieWave", 160000 ) -> 200000 | Q4: =Table2[[#This Row],[Net_Engagement]]/Table2[[#This Row],[Total_Budget]] -> 0.01675 | R4: =_xlfn.IFS( Table2[[#This Row],[Campaign_Name]]="SummerBeats", DATE(2024,6,15), Table2[[#This Row],[Campaign_Name]]="Wrapped2024", DATE(2024,12,1), Table2[[#This Row],[Campaign_Name]]="ChillVibes", DATE(2025,1,10), Table2[[#This Row],[Campaign_Name]]="IndieWave", DATE(2025,3,1) ) -> 45667 | S4: =_xlfn.IFS( Table2[[#This Row],[Campaign_Name]]="SummerBeats", DATE(2024,7,15), Table2[[#This Row],[Campaign_Name]]="Wrapped2024", DATE(2024,12,31), Table2[[#This Row],[Campaign_Name]]="ChillVibes", DATE(2025,2,10), Table2[[#This Row],[Campaign_Name]]="IndieWave", DATE(2025,3,31) ) -> 45698
A5: SP004 | B5: Instagram | C5: 45629 | D5: Text | E5: Wrapped is here! Relive your top tracks ðŸŽ§ | F5: 3173 | G5: 229 | H5: 197 | I5: 29604 | J5: 21809 | K5: 272 | L5: #SoundtrackOfLife,#NowPlaying | M5: ChillVibes | N5: =((F5+G5+H5)/I5)*100 -> 12.157141 | O5: =SUM(Table2[[#This Row],[Likes]],Table2[[#This Row],[Shares]],Table2[[#This Row],[Comments]]) -> 3599 | P5: =_xlfn.IFS( Table2[[#This Row],[Campaign_Name]]="SummerBeats", 175000, Table2[[#This Row],[Campaign_Name]]="Wrapped2024", 225000, Table2[[#This Row],[Campaign_Name]]="ChillVibes", 200000, Table2[[#This Row],[Campaign_Name]]="IndieWave", 160000 ) -> 200000 | Q5: =Table2[[#This Row],[Net_Engagement]]/Table2[[#This Row],[Total_Budget]] -> 0.017995 | R5: =_xlfn.IFS( Table2[[#This Row],[Campaign_Name]]="SummerBeats", DATE(2024,6,15), Table2[[#This Row],[Campaign_Name]]="Wrapped2024", DATE(2024,12,1), Table2[[#This Row],[Campaign_Name]]="ChillVibes", DATE(2025,1,10), Table2[[#This Row],[Campaign_Name]]="IndieWave", DATE(2025,3,1) ) -> 45667 | S5: =_xlfn.IFS( Table2[[#This Row],[Campaign_Name]]="SummerBeats", DATE(2024,7,15), Table2[[#This Row],[Campaign_Name]]="Wrapped2024", DATE(2024,12,31), Table2[[#This Row],[Campaign_Name]]="ChillVibes", DATE(2025,2,10), Table2[[#This Row],[Campaign_Name]]="IndieWave", DATE(2025,3,31) ) -> 45698
A6: SP005 | B6: YouTube | C6: 45388 | D6: Text | E6: Music that moves youâ€”only on Spotify. | F6: 2748 | G6: 145 | H6: 315 | I6: 24401 | J6: 61182 | K6: 200 | L6: #DiscoverWeekly,#SpotifyWrapped | M6: IndieWave | N6: =((F6+G6+H6)/I6)*100 -> 13.147002 | O6: =SUM(Table2[[#This Row],[Likes]],Table2[[#This Row],[Shares]],Table2[[#This Row],[Comments]]) -> 3208 | P6: =_xlfn.IFS( Table2[[#This Row],[Campaign_Name]]="SummerBeats", 175000, Table2[[#This Row],[Campaign_Name]]="Wrapped2024", 225000, Table2[[#This Row],[Campaign_Name]]="ChillVibes", 200000, Table2[[#This Row],[Campaign_Name]]="IndieWave", 160000 ) -> 160000 | Q6: =Table2[[#This Row],[Net_Engagement]]/Table2[[#This Row],[Total_Budget]] -> 0.02005 | R6: =_xlfn.IFS( Table2[[#This Row],[Campaign_Name]]="SummerBeats", DATE(2024,6,15), Table2[[#This Row],[Campaign_Name]]="Wrapped2024", DATE(2024,12,1), Table2[[#This Row],[Campaign_Name]]="ChillVibes", DATE(2025,1,10), Table2[[#This Row],[Campaign_Name]]="IndieWave", DATE(2025,3,1) ) -> 45717 | S6: =_xlfn.IFS( Table2[[#This Row],[Campaign_Name]]="SummerBeats", DATE(2024,7,15), Table2[[#This Row],[Campaign_Name]]="Wrapped2024", DATE(2024,12,31), Table2[[#This Row],[Campaign_Name]]="ChillVibes", DATE(2025,2,10), Table2[[#This Row],[Campaign_Name]]="IndieWave", DATE(2025,3,31) ) -> 45747
A7: SP006 | B7: YouTube | C7: 45456 | D7: Text | E7: Whatâ€™s your vibe today? #SpotifyHits | F7: 3882 | G7: 239 | H7: 275 | I7: 58748 | J7: 44646 | K7: 149 | L7: #DiscoverWeekly,#SpotifyWrapped | M7: IndieWave | N7: =((F7+G7+H7)/I7)*100 -> 7.4828079 | O7: =SUM(Table2[[#This Row],[Likes]],Table2[[#This Row],[Shares]],Table2[[#This Row],[Comments]]) -> 4396 | P7: =_xlfn.IFS( Table2[[#This Row],[Campaign_Name]]="SummerBeats", 175000, Table2[[#This Row],[Campaign_Name]]="Wrapped2024", 225000, Table2[[#This Row],[Campaign_Name]]="ChillVibes", 200000, Table2[[#This Row],[Campaign_Name]]="IndieWave", 160000 ) -> 160000 | Q7: =Table2[[#This Row],[Net_Engagement]]/Table2[[#This Row],[Total_Budget]] -> 0.027475 | R7: =_xlfn.IFS( Table2[[#This Row],[Campaign_Name]]="SummerBeats", DATE(2024,6,15), Table2[[#This Row],[Campaign_Name]]="Wrapped2024", DATE(2024,12,1), Table2[[#This Row],[Campaign_Name]]="ChillVibes", DATE(2025,1,10), Table2[[#This Row],[Campaign_Name]]="IndieWave", DATE(2025,3,1) ) -> 45717 | S7: =_xlfn.IFS( Table2[[#This Row],[Campaign_Name]]="SummerBeats", DATE(2024,7,15), Table2[[#This Row],[Campaign_Name]]="Wrapped2024", DATE(2024,12,31), Table2[[#This Row],[Campaign_Name]]="ChillVibes", DATE(2025,2,10), Table2[[#This Row],[Campaign_Name]]="IndieWave", DATE(2025,3,31) ) -> 45747
A8: SP007 | B8: Twitter | C8: 45645 | D8: Story | E8: Get into the groove with our new drop! | F8: 4674 | G8: 409 | H8: 327 | I8: 20756 | J8: 63599 | K8: 212 | L8: #SoundtrackOfLife,#NowPlaying | M8: ChillVibes | N8: =((F8+G8+H8)/I8)*100 -> 26.064752 | O8: =SUM(Table2[[#This Row],[Likes]],Table2[[#This Row],[Shares]],Table2[[#This Row],[Comments]]) -> 5410 | P8: =_xlfn.IFS( Table2[[#This Row],[Campaign_Name]]="SummerBeats", 175000, Table2[[#This Row],[Campaign_Name]]="Wrapped2024", 225000, Table2[[#This Row],[Campaign_Name]]="ChillVibes", 200000, Table2[[#This Row],[Campaign_Name]]="IndieWave", 160000 ) -> 200000 | Q8: =Table2[[#This Row],[Net_Engagement]]/Table2[[#This Row],[Total_Budget]] -> 0.02705 | R8: =_xlfn.IFS( Table2[[#This Row],[Campaign_Name]]="SummerBeats", DATE(2024,6,15), Table2[[#This Row],[Campaign_Name]]="Wrapped2024", DATE(2024,12,1), Table2[[#This Row],[Campaign_Name]]="ChillVibes", DATE(2025,1,10), Table2[[#This Row],[Campaign_Name]]="IndieWave", DATE(2025,3,1) ) -> 45667 | S8: =_xlfn.IFS( Table2[[#This Row],[Campaign_Name]]="SummerBeats", DATE(2024,7,15), Table2[[#This Row],[Campaign_Name]]="Wrapped2024", DATE(2024,12,31), Table2[[#This Row],[Campaign_Name]]="ChillVibes", DATE(2025,2,10), Table2[[#This Row],[Campaign_Name]]="IndieWave", DATE(2025,3,31) ) -> 45698
A9: SP008 | B9: Twitter | C9: 45421 | D9: Story | E9: Wrapped is here! Relive your top tracks ðŸŽ§ | F9: 1428 | G9: 347 | H9: 67 | I9: 21148 | J9: 19712 | K9: 120 | L9: #DiscoverWeekly,#MusicForEveryone | M9: ChillVibes | N9: =((F9+G9+H9)/I9)*100 -> 8.7100435 | O9: =SUM(Table2[[#This Row],[Likes]],Table2[[#This Row],[Shares]],Table2[[#This Row],[Comments]]) -> 1842 | P9: =_xlfn.IFS( Table2[[#This Row],[Campaign_Name]]="SummerBeats", 175000, Table2[[#This Row],[Campaign_Name]]="Wrapped2024", 225000, Table2[[#This Row],[Campaign_Name]]="ChillVibes", 200000, Table2[[#This Row],[Campaign_Name]]="IndieWave", 160000 ) -> 200000 | Q9: =Table2[[#This Row],[Net_Engagement]]/Table2[[#This Row],[Total_Budget]] -> 0.00921 | R9: =_xlfn.IFS( Table2[[#This Row],[Campaign_Name]]="SummerBeats", DATE(2024,6,15), Table2[[#This Row],[Campaign_Name]]="Wrapped2024", DATE(2024,12,1), Table2[[#This Row],[Campaign_Name]]="ChillVibes", DATE(2025,1,10), Table2[[#This Row],[Campaign_Name]]="IndieWave", DATE(2025,3,1) ) -> 45667 | S9: =_xlfn.IFS( Table2[[#This Row],[Campaign_Name]]="SummerBeats", DATE(2024,7,15), Table2[[#This Row],[Campaign_Name]]="Wrapped2024", DATE(2024,12,31), Table2[[#This Row],[Campaign_Name]]="ChillVibes", DATE(2025,2,10), Table2[[#This Row],[Campaign_Name]]="IndieWave", DATE(2025,3,31) ) -> 45698
A10: SP009 | B10: Twitter | C10: 45823 | D10: Text | E10: Top trending tracks updated daily! | F10: 4432 | G10: 223 | H10: 299 | I10: 59016 | J10: 21742 | K10: 171 | L10: #NowPlaying | M10: ChillVibes | N10: =((F10+G10+H10)/I10)*100 -> 8.3943337 | O10: =SUM(Table2[[#This Row],[Likes]],Table2[[#This Row],[Shares]],Table2[[#This Row],[Comments]]) -> 4954 | P10: =_xlfn.IFS( Table2[[#This Row],[Campaign_Name]]="SummerBeats", 175000, Table2[[#This Row],[Campaign_Name]]="Wrapped2024", 225000, Table2[[#This Row],[Campaign_Name]]="ChillVibes", 200000, Table2[[#This Row],[Campaign_Name]]="IndieWave", 160000 ) -> 200000 | Q10: =Table2[[#This Row],[Net_Engagement]]/Table2[[#This Row],[Total_Budget]] -> 0.02477 | R10: =_xlfn.IFS( Table2[[#This Row],[Campaign_Name]]="SummerBeats", DATE(2024,6,15), Table2[[#This Row],[Campaign_Name]]="Wrapped2024", DATE(2024,12,1), Table2[[#This Row],[Campaign_Name]]="ChillVibes", DATE(2025,1,10), Table2[[#This Row],[Campaign_Name]]="IndieWave", DATE(2025,3,1) ) -> 45667 | S10: =_xlfn.IFS( Table2[[#This Row],[Campaign_Name]]="SummerBeats", DATE(2024,7,15), Table2[[#This Row],[Campaign_Name]]="Wrapped2024", DATE(2024,12,31), Table2[[#This Row],[Campaign_Name]]="ChillVibes", DATE(2025,2,10), Table2[[#This Row],[Campaign_Name]]="IndieWave", DATE(2025,3,31) ) -> 45698
A11: SP010 | B11: Twitter | C11: 45630 | D11: Text | E11: Wrapped is here! Relive your top tracks ðŸŽ§ | F11: 2357 | G11: 274 | H11: 172 | I11: 21566 | J11: 66829 | K11: 284 | L11: #NowPlaying | M11: ChillVibes | N11: =((F11+G11+H11)/I11)*100 -> 12.997311 | O11: =SUM(Table2[[#This Row],[Likes]],Table2[[#This Row],[Shares]],Table2[[#This Row],[Comments]]) -> 2803 | P11: =_xlfn.IFS( Table2[[#This Row],[Campaign_Name]]="SummerBeats", 175000, Table2[[#This Row],[Campaign_Name]]="Wrapped2024", 225000, Table2[[#This Row],[Campaign_Name]]="ChillVibes", 200000, Table2[[#This Row],[Campaign_Name]]="IndieWave", 160000 ) -> 200000 | Q11: =Table2[[#This Row],[Net_Engagement]]/Table2[[#This Row],[Total_Budget]] -> 0.014015 | R11: =_xlfn.IFS( Table2[[#This Row],[Campaign_Name]]="SummerBeats", DATE(2024,6,15), Table2[[#This Row],[Campaign_Name]]="Wrapped2024", DATE(2024,12,1), Table2[[#This Row],[Campaign_Name]]="ChillVibes", DATE(2025,1,10), Table2[[#This Row],[Campaign_Name]]="IndieWave", DATE(2025,3,1) ) -> 45667 | S11: =_xlfn.IFS( Table2[[#This Row],[Campaign_Name]]="SummerBeats", DATE(2024,7,15), Table2[[#This Row],[Campaign_Name]]="Wrapped2024", DATE(2024,12,31), Table2[[#This Row],[Campaign_Name]]="ChillVibes", DATE(2025,2,10), Table2[[#This Row],[Campaign_Name]]="IndieWave", DATE(2025,3,31) ) -> 45698
A12: SP011 | B12: Twitter | C12: 45357 | D12: Text | E12: Discover fresh beats on Spotify! | F12: 1971 | G12: 370 | H12: 306 | I12: 31316 | J12: 27897 | K12: 88 | L12: #SoundtrackOfLife | M12: IndieWave | N12: =((F12+G12+H12)/I12)*100 -> 8.4525482 | O12: =SUM(Table2[[#This Row],[Likes]],Table2[[#This Row],[Shares]],Table2[[#This Row],[Comments]]) -> 2647 | P12: =_xlfn.IFS( Table2[[#This Row],[Campaign_Name]]="SummerBeats", 175000, Table2[[#This Row],[Campaign_Name]]="Wrapped2024", 225000, Table2[[#This Row],[Campaign_Name]]="ChillVibes", 200000, Table2[[#This Row],[Campaign_Name]]="IndieWave", 160000 ) -> 160000 | Q12: =Table2[[#This Row],[Net_Engagement]]/Table2[[#This Row],[Total_Budget]] -> 0.01654375 | R12: =_xlfn.IFS( Table2[[#This Row],[Campaign_Name]]="SummerBeats", DATE(2024,6,15), Table2[[#This Row],[Campaign_Name]]="Wrapped2024", DATE(2024,12,1), Table2[[#This Row],[Campaign_Name]]="ChillVibes", DATE(2025,1,10), Table2[[#This Row],[Campaign_Name]]="IndieWave", DATE(2025,3,1) ) -> 45717 | S12: =_xlfn.IFS( Table2[[#This Row],[Campaign_Name]]="SummerBeats", DATE(2024,7,15), Table2[[#This Row],[Campaign_Name]]="Wrapped2024", DATE(2024,12,31), Table2[[#This Row],[Campaign_Name]]="ChillVibes", DATE(2025,2,10), Table2[[#This Row],[Campaign_Name]]="IndieWave", DATE(2025,3,31) ) -> 45747
A13: SP012 | B13: Instagram | C13: 45426 | D13: Text | E13: Discover fresh beats on Spotify! | F13: 1485 | G13: 353 | H13: 244 | I13: 38419 | J13: 38556 | K13: 86 | L13: #SoundtrackOfLife,#NowPlaying | M13: ChillVibes | N13: =((F13+G13+H13)/I13)*100 -> 5.4191936 | O13: =SUM(Table2[[#This Row],[Likes]],Table2[[#This Row],[Shares]],Table2[[#This Row],[Comments]]) -> 2082 | P13: =_xlfn.IFS( Table2[[#This Row],[Campaign_Name]]="SummerBeats", 175000, Table2[[#This Row],[Campaign_Name]]="Wrapped2024", 225000, Table2[[#This Row],[Campaign_Name]]="ChillVibes", 200000, Table2[[#This Row],[Campaign_Name]]="IndieWave", 160000 ) -> 200000 | Q13: =Table2[[#This Row],[Net_Engagement]]/Table2[[#This Row],[Total_Budget]] -> 0.01041 | R13: =_xlfn.IFS( Table2[[#This Row],[Campaign_Name]]="SummerBeats", DATE(2024,6,15), Table2[[#This Row],[Campaign_Name]]="Wrapped2024", DATE(2024,12,1), Table2[[#This Row],[Campaign_Name]]="ChillVibes", DATE(2025,1,10), Table2[[#This Row],[Campaign_Name]]="IndieWave", DATE(2025,3,1) ) -> 45667 | S13: =_xlfn.IFS( Table2[[#This Row],[Campaign_Name]]="SummerBeats", DATE(2024,7,15), Table2[[#This Row],[Campaign_Name]]="Wrapped2024", DATE(2024,12,31), Table2[[#This Row],[Campaign_Name]]="ChillVibes", DATE(2025,2,10), Table2[[#This Row],[Campaign_Name]]="IndieWave", DATE(2025,3,31) ) -> 45698
... A301: SP300 | B301: Instagram | C301: 45329 | D301: Text | E301: Music that moves youâ€”only on Spotify. | F301: 1883 | G301: 432 | H301: 397 | I301: 28759 | J301: 18691 | K301: 270 | L301: #SoundtrackOfLife,#NowPlaying | M301: ChillVibes | N301: =((F301+G301+H301)/I301)*100 -> 9.4300914 | O301: =SUM(Table2[[#This Row],[Likes]],Table2[[#This Row],[Shares]],Table2[[#This Row],[Comments]]) -> 2712 | P301: =_xlfn.IFS( Table2[[#This Row],[Campaign_Name]]="SummerBeats", 175000, Table2[[#This Row],[Campaign_Name]]="Wrapped2024", 225000, Table2[[#This Row],[Campaign_Name]]="ChillVibes", 200000, Table2[[#This Row],[Campaign_Name]]="IndieWave", 160000 ) -> 200000 | Q301: =Table2[[#This Row],[Net_Engagement]]/Table2[[#This Row],[Total_Budget]] -> 0.01356 | R301: =_xlfn.IFS( Table2[[#This Row],[Campaign_Name]]="SummerBeats", DATE(2024,6,15), Table2[[#This Row],[Campaign_Name]]="Wrapped2024", DATE(2024,12,1), Table2[[#This Row],[Campaign_Name]]="ChillVibes", DATE(2025,1,10), Table2[[#This Row],[Campaign_Name]]="IndieWave", DATE(2025,3,1) ) -> 45667 | S301: =_xlfn.IFS( Table2[[#This Row],[Campaign_Name]]="SummerBeats", DATE(2024,7,15), Table2[[#This Row],[Campaign_Name]]="Wrapped2024", DATE(2024,12,31), Table2[[#This Row],[Campaign_Name]]="ChillVibes", DATE(2025,2,10), Table2[[#This Row],[Campaign_Name]]="IndieWave", DATE(2025,3,31) ) -> 45698

Sheet Engagement Summary
A1: Week_Start_Date | B1: Platform | C1: New_Followers | D1: Unfollows | E1: Total_Followers | F1: Engagement_Rate | G1: Ad_Spend | H1: Net_Followers | I1: Corelation
A2: 45810 | B2: YouTube | C2: 637 | D2: 68 | E2: 115694 | F2: 9.99 | G2: 12562 | H2: =C2-D2 -> 569 | I2: =CORREL(Table7[Net_Followers],Table7[Ad_Spend]) -> -0.01691599 | K2: =MAX(H:H) -> 1397
A3: 45845 | B3: Instagram | C3: 974 | D3: 143 | E3: 247965 | F3: 9.98 | G3: 12767 | H3: =C3-D3 -> 831 | I3: =CORREL(Table7[Net_Followers],Table7[Ad_Spend]) -> -0.01691599 | K3: =INDEX(A:A,MATCH(MAX(C:C),C:C,0))&" - "&INDEX(B:B,MATCH(MAX(C:C),C:C,0)) -> 45866 - YouTube
A4: 45453 | B4: YouTube | C4: 545 | D4: 93 | E4: 391621 | F4: 9.96 | G4: 22029 | H4: =C4-D4 -> 452 | I4: =CORREL(Table7[Net_Followers],Table7[Ad_Spend]) -> -0.01691599 | K4: =MAX(E:E) -> 397607
A5: 45845 | B5: Twitter | C5: 1155 | D5: 122 | E5: 387352 | F5: 9.93 | G5: 12170 | H5: =C5-D5 -> 1033 | I5: =CORREL(Table7[Net_Followers],Table7[Ad_Spend]) -> -0.01691599
A6: 45446 | B6: Instagram | C6: 1402 | D6: 68 | E6: 124562 | F6: 9.92 | G6: 23125 | H6: =C6-D6 -> 1334 | I6: =CORREL(Table7[Net_Followers],Table7[Ad_Spend]) -> -0.01691599
A7: 45509 | B7: Instagram | C7: 1449 | D7: 96 | E7: 200636 | F7: 9.92 | G7: 15613 | H7: =C7-D7 -> 1353 | I7: =CORREL(Table7[Net_Followers],Table7[Ad_Spend]) -> -0.01691599
A8: 45600 | B8: Twitter | C8: 1463 | D8: 73 | E8: 348877 | F8: 9.91 | G8: 26273 | H8: =C8-D8 -> 1390 | I8: =CORREL(Table7[Net_Followers],Table7[Ad_Spend]) -> -0.01691599
A9: 45684 | B9: Instagram | C9: 566 | D9: 225 | E9: 368984 | F9: 9.82 | G9: 9592 | H9: =C9-D9 -> 341 | I9: =CORREL(Table7[Net_Followers],Table7[Ad_Spend]) -> -0.01691599
A10: 45747 | B10: Twitter | C10: 1232 | D10: 254 | E10: 107718 | F10: 9.71 | G10: 13740 | H10: =C10-D10 -> 978 | I10: =CORREL(Table7[Net_Followers],Table7[Ad_Spend]) -> -0.01691599
A11: 45621 | B11: YouTube | C11: 1313 | D11: 159 | E11: 197183 | F11: 9.71 | G11: 6625 | H11: =C11-D11 -> 1154 | I11: =CORREL(Table7[Net_Followers],Table7[Ad_Spend]) -> -0.01691599
A12: 45467 | B12: YouTube | C12: 844 | D12: 144 | E12: 126015 | F12: 9.65 | G12: 22456 | H12: =C12-D12 -> 700 | I12: =CORREL(Table7[Net_Followers],Table7[Ad_Spend]) -> -0.01691599
A13: 45852 | B13: Twitter | C13: 670 | D13: 242 | E13: 281913 | F13: 9.62 | G13: 16377 | H13: =C13-D13 -> 428 | I13: =CORREL(Table7[Net_Followers],Table7[Ad_Spend]) -> -0.01691599
A14: 45740 | B14: Twitter | C14: 975 | D14: 162 | E14: 124497 | F14: 9.58 | G14: 26618 | H14: =C14-D14 -> 813 | I14: =CORREL(Table7[Net_Followers],Table7[Ad_Spend]) -> -0.01691599
A15: 45579 | B15: YouTube | C15: 1457 | D15: 215 | E15: 325325 | F15: 9.58 | G15: 14178 | H15: =C15-D15 -> 1242 | I15: =CORREL(Table7[Net_Followers],Table7[Ad_Spend]) -> -0.01691599
A16: 45565 | B16: Twitter | C16: 998 | D16: 154 | E16: 179781 | F16: 9.58 | G16: 12115 | H16: =C16-D16 -> 844 | I16: =CORREL(Table7[Net_Followers],Table7[Ad_Spend]) -> -0.01691599
... A201: 45894 | B201: YouTube | C201: 791 | D201: 273 | E201: 144049 | F201: 3.08 | G201: 5281 | H201: =C201-D201 -> 518 | I201: =CORREL(Table7[Net_Followers],Table7[Ad_Spend]) -> -0.01691599

Sheet Campaign Metadata
A1: Campaign_Name | B1: Start_Date | C1: End_Date | D1: Objective | E1: Total_Budget | F1: Target_Platforms | G1: Primary_Hashtags
A2: SummerBeats | B2: 2024-06-15 | C2: 2024-07-15 | D2: Brand Awareness | E2: 175000 | F2: Instagram,YouTube | G2: #SpotifyWrapped,#MusicForEveryone
A3: Wrapped2024 | B3: 2024-12-01 | C3: 2024-12-31 | D3: Engagement | E3: 225000 | F3: Twitter,YouTube | G3: #SpotifyWrapped,#NowPlaying
A4: ChillVibes | B4: 2025-01-10 | C4: 2025-02-10 | D4: Product Launch | E4: 200000 | F4: Instagram,Twitter | G4: #ChillVibes,#SoundtrackOfLife
A5: IndieWave | B5: 2025-03-01 | C5: 2025-03-31 | D5: Traffic | E5: 160000 | F5: Facebook,Instagram | G5: #DiscoverWeekly,#IndieWave
